---
note_type: note
tags:
  - web_development
  - javascript
  - api
mn: "[[12.5 Javascript]]"
kt: theorical
checked: false
---
[[12.5 Javascript|JavaScript]]

`try/catch` blocks are valid within sync and, specially, async functions. This method won't crash the application and allow to separate the main logic from the error handling-code. However, its overuse can hide some bugs or impact performance if used excessively.

```js
async function getPersonsInfo(name) {
  try {
    const people = await server.getPeople();
    const person = people.find(person => person.name === name);
    if (!person) {
      throw new Error(`Person with name ${name} not found`);
    }
    return person;
  } catch (error) {
    console.error(`Error fetching person's info: ${error.message}`);
    // Depending on your error handling strategy, you might want to:
    // - Rethrow the error: throw error;
    // - Return null or a default value: return null;
    // - Or handle it in some other way
    throw error; // For this example, we'll rethrow the error
  }
}
```

Though I can append `catch()` after an async function invocation, this is easier. 

I don't always have to throw an error inside of the block:

```js
async function f() {

  try {
    let response = await fetch('/no-user-here');
    let user = await response.json();
  } catch(err) {
    // catches errors both in fetch and response.json
    alert(err);
  }
}

f();
```

If I don't want to use try/catch blocks, the promise return by the `async` function will be rejected, so I can append a catch to handle it:

```js
async function f() {
  let response = await fetch('http://no-such-url');
}

// f() becomes a rejected promise
f().catch(alert); 
```