---
note_type: note
tags:
  - web_development
  - javascript
  - promises
mn: "[[12.5 Javascript]]"
kt: theorical
checked: false
---
[[12.5 Javascript|JavaScript]]

`Promise.all` takes an array of promises and fires one callback once they **are all** resolved. If any promise rejects, it immediately rejects with the reason of the first rejected promise.

If successful, returns an array of the fulfilled values, in the order of the input promises.

```js
Promise.all([promise1, promise2]).then(function(results) {
	// Both promises resolved
})
.catch(function(error) {
	// One or more promises was rejected
});
```

```js
const promises = [Promise.resolve(1), Promise.resolve(2), Promise.resolve(3)];
Promise.all(promises)
  .then(results => console.log(results))  // [1, 2, 3]
  .catch(error => console.error(error));

// If one promise rejects:
const promisesWithReject = [Promise.resolve(1), Promise.reject('Error'), Promise.resolve(3)];
Promise.all(promisesWithReject)
  .then(results => console.log(results))  // This won't be called
  .catch(error => console.error(error));  // 'Error'
```


```js
// Simulated asynchronous functions that return promises
function fetchUserData(userId) {
  return new Promise((resolve, reject) => {
    setTimeout(() => {
      if (userId > 0) {
        resolve({ id: userId, name: `User ${userId}` });
      } else {
        reject(new Error('Invalid user ID'));
      }
    }, Math.random() * 1000); // Random delay to simulate network latency
  });
}

function fetchUserPosts(userId) {
  return new Promise((resolve, reject) => {
    setTimeout(() => {
      if (userId > 0) {
        resolve([
          { id: 1, title: `Post 1 by User ${userId}` },
          { id: 2, title: `Post 2 by User ${userId}` }
        ]);
      } else {
        reject(new Error('Invalid user ID'));
      }
    }, Math.random() * 1000);
  });
}

// Function to fetch both user data and posts
function fetchUserInfo(userId) {
  return Promise.all([
    fetchUserData(userId),
    fetchUserPosts(userId)
  ]);
}

// Usage
console.log('Fetching user info...');
fetchUserInfo(1)
  .then(([userData, userPosts]) => {
    console.log('User Data:', userData);
    console.log('User Posts:', userPosts);
  })
  .catch(error => {
    console.error('Error:', error.message);
  })
  .finally(() => {
    console.log('Fetch operation completed.');
  });

// Example with multiple users
const userIds = [1, 2, 3];
Promise.all(userIds.map(fetchUserInfo))
  .then(usersInfo => {
    usersInfo.forEach(([userData, userPosts], index) => {
      console.log(`\nInfo for User ${userIds[index]}:`);
      console.log('User Data:', userData);
      console.log('User Posts:', userPosts);
    });
  })
  .catch(error => {
    console.error('Error:', error.message);
  });
  
```

When using promise.all, the catch fires for the first rejection encountered.

```js
let req1 = new Promise(function(resolve, reject) { 
	// A mock async action using setTimeout
	setTimeout(function() { resolve('First!'); }, 4000);
});
let req2 = new Promise(function(resolve, reject) { 
	// A mock async action using setTimeout
	setTimeout(function() { reject('Second!'); }, 3000);
});
Promise.all([req1, req2]).then(function(results) {
	console.log('Then: ', results);
}).catch(function(err) {
	console.log('Catch: ', err);
});

// From the console:
// Catch: Second!
```